Workbook

Sheet Dashboard & Statistik
B2: Data Analytics & Ringkasan Wisata Bandung
B3: Informasi matriks utama dan persebaran kategori destinasi wisata
B5: Total Destinasi | D5: Prioritas 1 (Utama) | F5: Prioritas 2 (Medium) | H5: Prioritas 3 (Rendah)
B6: =COUNTA('Daftar Destinasi Wisata'!C6:C44) | D6: =COUNTIF('Daftar Destinasi Wisata'!B6:B44, 1) | F6: =COUNTIF('Daftar Destinasi Wisata'!B6:B44, 2) | H6: =COUNTIF('Daftar Destinasi Wisata'!B6:B44, 3)
B9: Analisis Berdasarkan Kategori
B11: Kategori | C11: Jumlah
B12: Desa Wisata | C12: =COUNTIF('Daftar Destinasi Wisata'!E6:E44, "Desa Wisata")
B13: Penginapan Wisata | C13: =COUNTIF('Daftar Destinasi Wisata'!E6:E44, "Penginapan Wisata")
B14: Rekreasi Keluarga | C14: =COUNTIF('Daftar Destinasi Wisata'!E6:E44, "Rekreasi Keluarga")
B15: Taman Kota | C15: =COUNTIF('Daftar Destinasi Wisata'!E6:E44, "Taman Kota")
B16: Tempat Belajar | C16: =COUNTIF('Daftar Destinasi Wisata'!E6:E44, "Tempat Belajar")
B17: Tempat Belanja | C17: =COUNTIF('Daftar Destinasi Wisata'!E6:E44, "Tempat Belanja")
B18: Tempat Camping | C18: =COUNTIF('Daftar Destinasi Wisata'!E6:E44, "Tempat Camping")
B19: Tempat Kuliner | C19: =COUNTIF('Daftar Destinasi Wisata'!E6:E44, "Tempat Kuliner")
B20: Tempat Seni | C20: =COUNTIF('Daftar Destinasi Wisata'!E6:E44, "Tempat Seni")
B21: Wahana Air | C21: =COUNTIF('Daftar Destinasi Wisata'!E6:E44, "Wahana Air")
B22: Wisata Alam | C22: =COUNTIF('Daftar Destinasi Wisata'!E6:E44, "Wisata Alam")
B23: Wisata Petualangan | C23: =COUNTIF('Daftar Destinasi Wisata'!E6:E44, "Wisata Petualangan")
B24: Wisata Satwa | C24: =COUNTIF('Daftar Destinasi Wisata'!E6:E44, "Wisata Satwa")
B25: Total Keseluruhan | C25: =SUM(C12:C24)

Sheet Daftar Destinasi Wisata
B2: Daftar Referensi Lokasi & Foto Wisata Bandung
B3: Koleksi data destinasi lengkap berdasarkan prioritas dan kategori kunjungan
B5: Prioritas | C5: ID Lokasi | D5: Nama Tempat Wisata | E5: Kategori Destinasi | F5: Link Foto / Visual
B6: 1 | C6: LOC-017 | D6: Cihampelas Walk | E6: Tempat Belanja | F6: =HYPERLINK("https://images.unsplash.com/photo-1567401893414-76b7b1e5a7a5?w=800&q=80", "Lihat Foto ↗")
B7: 1 | C7: LOC-120 | D7: Rumah Guguk | E7: Wisata Satwa | F7: =HYPERLINK("https://images.unsplash.com/photo-1548199973-03cce0bbc87b?w=800&q=80", "Lihat Foto ↗")
B8: 1 | C8: LOC-121 | D8: NuArt Sculpture Park | E8: Tempat Seni | F8: =HYPERLINK("https://images.unsplash.com/photo-1579783900882-c0d3dad7b119?w=800&q=80", "Lihat Foto ↗")
B9: 1 | C9: LOC-133 | D9: Punclut Bandung (Puncak Ciumbuleuit) | E9: Wisata Alam | F9: =HYPERLINK("https://images.unsplash.com/photo-1501785888041-af3ef285b470?w=800&q=80", "Lihat Foto ↗")
B10: 1 | C10: LOC-134 | D10: Bukit Bintang Bandung (Patahan Lembang) | E10: Wisata Alam | F10: =HYPERLINK("https://images.unsplash.com/photo-1475274047050-1d0c0975c63e?w=800&q=80", "Lihat Foto ↗")
B11: 1 | C11: LOC-148 | D11: Pesona Nirwana Waterpark | E11: Wahana Air | F11: =HYPERLINK("https://images.unsplash.com/photo-1519817650390-64a93db51149?w=800&q=80", "Lihat Foto ↗")
B12: 1 | C12: LOC-173 | D12: Cakrawala Nature Sparkling Restaurant | E12: Tempat Kuliner | F12: =HYPERLINK("https://images.unsplash.com/photo-1517248135467-4c7edcad34c4?w=800&q=80", "Lihat Foto ↗")
B13: 1 | C13: LOC-174 | D13: Lereng Anteng Panoramic Coffee | E13: Tempat Kuliner | F13: =HYPERLINK("https://images.unsplash.com/photo-1554118811-1e0d58224f24?w=800&q=80", "Lihat Foto ↗")
B14: 1 | C14: LOC-177 | D14: Wahoo Waterworld | E14: Wahana Air | F14: =HYPERLINK("https://images.unsplash.com/photo-1583417319070-4a69db38a482?w=800&q=80", "Lihat Foto ↗")
B15: 1 | C15: LOC-178 | D15: De'Ranch Lembang | E15: Wisata Satwa | F15: =HYPERLINK("https://images.unsplash.com/photo-1553284965-83fd3e82fa52?w=800&q=80", "Lihat Foto ↗")
B16: 1 | C16: LOC-180 | D16: Cimory Dairyland Lembang | E16: Wisata Satwa | F16: =HYPERLINK("https://images.unsplash.com/photo-1570042225831-d98fa7577f1e?w=800&q=80", "Lihat Foto ↗")
B17: 1 | C17: LOC-181 | D17: Noah's Park Lembang | E17: Rekreasi Keluarga | F17: =HYPERLINK("https://images.unsplash.com/photo-1566415712160-b51317ded491?w=800&q=80", "Lihat Foto ↗")
B18: 1 | C18: LOC-220 | D18: Nimo Jungle Hot Spring | E18: Wisata Alam | F18: =HYPERLINK("https://images.unsplash.com/photo-1540555700478-4be289fbecef?w=800&q=80", "Lihat Foto ↗")
B19: 2 | C19: LOC-135 | D19: Taman Main Mili-Mili & Hutan Mycelia | E19: Rekreasi Keluarga | F19: =HYPERLINK("https://images.unsplash.com/photo-1448375240586-882707db888b?w=800&q=80", "Lihat Foto ↗")
B20: 2 | C20: LOC-139 | D20: Kawah Rengganis Ciwidey | E20: Wisata Alam | F20: =HYPERLINK("https://images.unsplash.com/photo-1464822759023-fed622ff2c3b?w=800&q=80", "Lihat Foto ↗")
B21: 2 | C21: LOC-149 | D21: Taman Wisata Alam Cimanggu | E21: Wisata Alam | F21: =HYPERLINK("https://images.unsplash.com/photo-1473448912268-2022ce9509d8?w=800&q=80", "Lihat Foto ↗")
B22: 2 | C22: LOC-158 | D22: Situ Ninah (Situ Datar) | E22: Wisata Alam | F22: =HYPERLINK("https://images.unsplash.com/photo-1504280390367-361c6d9f38f4?w=800&q=80", "Lihat Foto ↗")
B23: 2 | C23: LOC-163 | D23: Kampung Adat Cikondang | E23: Desa Wisata | F23: =HYPERLINK("https://images.unsplash.com/photo-1590001155093-a3c66ab0c3ff?w=800&q=80", "Lihat Foto ↗")
B24: 2 | C24: LOC-164 | D24: Java Preanger Gunung Tilu | E24: Wisata Alam | F24: =HYPERLINK("https://images.unsplash.com/photo-1513836279014-a89f7a76ae86?w=800&q=80", "Lihat Foto ↗")
B25: 2 | C25: LOC-176 | D25: Padepokan Dayang Sumbi | E25: Tempat Belajar | F25: =HYPERLINK("https://images.unsplash.com/photo-1503676260728-1c00da094a0b?w=800&q=80", "Lihat Foto ↗")
B26: 2 | C26: LOC-182 | D26: Pine Forest Camp Lembang | E26: Tempat Camping | F26: =HYPERLINK("https://images.unsplash.com/photo-1478131143081-80f7f84ca84d?w=800&q=80", "Lihat Foto ↗")
B27: 2 | C27: LOC-183 | D27: Imah Seniman Lembang | E27: Penginapan Wisata | F27: =HYPERLINK("https://images.unsplash.com/photo-1566073771259-6a8506099945?w=800&q=80", "Lihat Foto ↗")
B28: 2 | C28: LOC-186 | D28: Indiana Camp Lembang | E28: Tempat Camping | F28: =HYPERLINK("https://images.unsplash.com/photo-1510312305653-8ed496efae75?w=800&q=80", "Lihat Foto ↗")
B29: 2 | C29: LOC-187 | D29: Curug Layung | E29: Wisata Alam | F29: =HYPERLINK("https://images.unsplash.com/photo-1432406186174-2b24f4a6fe9c?w=800&q=80", "Lihat Foto ↗")
B30: 2 | C30: LOC-190 | D30: Curug Anom | E30: Wisata Alam | F30: =HYPERLINK("https://images.unsplash.com/photo-1470071459604-3b5ec3a7fe05?w=800&q=80", "Lihat Foto ↗")
B31: 2 | C31: LOC-193 | D31: Sanghyang Poek | E31: Wisata Alam | F31: =HYPERLINK("https://images.unsplash.com/photo-1502082553048-f009c37129b9?w=800&q=80", "Lihat Foto ↗")
B32: 2 | C32: LOC-195 | D32: Sungai Cikahuripan Green Canyon Saguling | E32: Wisata Alam | F32: =HYPERLINK("https://images.unsplash.com/photo-1546182990-dffeafbe841d?w=800&q=80", "Lihat Foto ↗")
B33: 2 | C33: LOC-198 | D33: Tebing Gunung Hawu | E33: Wisata Alam | F33: =HYPERLINK("https://images.unsplash.com/photo-1464822759023-fed622ff2c3b?w=800&q=80", "Lihat Foto ↗")
B34: 2 | C34: LOC-201 | D34: Curug Batu Templek | E34: Wisata Alam | F34: =HYPERLINK("https://images.unsplash.com/photo-1508193638397-1c4234db14d8?w=800&q=80", "Lihat Foto ↗")
B35: 2 | C35: LOC-213 | D35: Taman Cibeunying | E35: Taman Kota | F35: =HYPERLINK("https://images.unsplash.com/photo-1585320806297-9794b3e4eeae?w=800&q=80", "Lihat Foto ↗")
B36: 2 | C36: LOC-215 | D36: Taman Pramuka Bandung | E36: Taman Kota | F36: =HYPERLINK("https://images.unsplash.com/photo-1596436889106-be35e843f974?w=800&q=80", "Lihat Foto ↗")
B37: 2 | C37: LOC-217 | D37: Karang Setra Waterland | E37: Wahana Air | F37: =HYPERLINK("https://images.unsplash.com/photo-1576013551627-0cc20b96c2a7?w=800&q=80", "Lihat Foto ↗")
B38: 2 | C38: LOC-219 | D38: Museum Inggit Garnasih | E38: Tempat Belajar | F38: =HYPERLINK("https://images.unsplash.com/photo-1580537659466-0a9bfa916a54?w=800&q=80", "Lihat Foto ↗")
B39: 2 | C39: LOC-222 | D39: Nuansa Riung Gunung | E39: Wisata Alam | F39: =HYPERLINK("https://images.unsplash.com/photo-1534447677768-be436bb09401?w=800&q=80", "Lihat Foto ↗")
B40: 2 | C40: LOC-224 | D40: Sungai Palayangan Rafting | E40: Wisata Petualangan | F40: =HYPERLINK("https://images.unsplash.com/photo-1530866495561-507c9faab2ed?w=800&q=80", "Lihat Foto ↗")
B41: 2 | C41: LOC-225 | D41: Curug Ceret Pangalengan | E41: Wisata Alam | F41: =HYPERLINK("https://images.unsplash.com/photo-1518495973542-4542c06a5843?w=800&q=80", "Lihat Foto ↗")
B42: 2 | C42: LOC-226 | D42: Gunung Nini Pangalengan | E42: Wisata Alam | F42: =HYPERLINK("https://images.unsplash.com/photo-1507525428034-b723cf961d3e?w=800&q=80", "Lihat Foto ↗")
...
